<robot xmlns:xacro="http://ros.org/wiki/xacro" name="sia5">
<xacro:property name="M_PI" value="3.14159"/>
<xacro:property name="M_SCALE" value="0.001"/>
<xacro:property name="F10_HEIGHT" value="0.004"/>
<xacro:property name="F4_HEIGHT" value="0.0525"/>
<xacro:property name="F3_HEIGHT" value="0.009"/>
<xacro:property name="AX12_HEIGHT" value="0.0385"/>
<xacro:property name="AX12_WIDTH" value="0.038"/>
<xacro:property name="F2_HEIGHT" value="0.0265"/>



<!--  File Include  -->
<xacro:include filename="$(find motoman_description)/robots/sia5/sia5.urdf.xacro"/>
<xacro:include filename="$(find turtlebot_arm_description)/urdf/arm_hardware.xacro"/>





<!--  gripper joint  -->
<dynamixel_AX12_fixed parent="tool0" name="gripper_servo">
<origin xyz="0.02 -0.01 0" rpy="${M_PI/2} 0 0"/>
</dynamixel_AX12_fixed>

<!--  finger 1  -->
<joint name="gripper_joint" type="revolute">
<origin xyz="0 0 0" rpy="0 0 0"/>
<axis xyz="0 1 0"/>
<limit effort="30" velocity="0.785" lower="-0.40" upper="0.46"/>
<parent link="gripper_servo_link"/>
<child link="gripper_active_link"/>
</joint>
<link name="gripper_active_link">
<inertial>
<mass value="0.00001"/>
<origin xyz="0 0 0"/>
<inertia ixx="1.0" ixy="0.0" ixz="0.0" iyy="1.0" iyz="0.0" izz="1.0"/>
</inertial>
<visual>
<origin xyz=" 0 0 0 " rpy="0 0 0"/>
<geometry>
<mesh filename="package://turtlebot_arm_description/meshes/F2.stl" scale="${M_SCALE} ${M_SCALE} ${M_SCALE}"/>
</geometry>
<material name="white"/>
</visual>
<collision>
<origin xyz="0.0 0.0 0.00775" rpy="0 0 0"/>
<geometry>
<box size="0.025 0.0485 0.0375"/>
</geometry>
</collision>
</link>
<finger_fixed parent="gripper_active_link" name="gripper_active_finger" color="green">
<origin xyz="0 0 ${F2_HEIGHT}" rpy="0 0 0"/>
</finger_fixed>

<!--  finger 2  -->
<bioloid_F3_fixed parent="gripper_servo_link" name="gripper_static" color="white">
<origin xyz="0 0 ${-AX12_HEIGHT-F10_HEIGHT+0.001}" rpy="0 ${M_PI} 0"/>
</bioloid_F3_fixed>
<finger_fixed parent="gripper_static_link" name="gripper_static_finger" color="green">
<origin xyz="0 0 0" rpy="0 0 ${M_PI}"/>
</finger_fixed>






<!--  Joint
<joint name="joint_gripper" type="fixed">
<origin rpy="-0.1745 0 0" xyz="0.0001 0 0"/>
<parent link="tool0"/>
<child link="gripper_link"/>
</joint>
<joint name="joint_balloon" type="fixed">
<origin rpy="0.1745 0 0" xyz="0.108 0 0"/>
<parent link="gripper_link"/>
<child link="balloon"/>
</joint>         -->


</robot>
